Workbook

Sheet Regular Clients
A1: Regular Clients - booked directly with Zaria Court
A2: Booked directly with Zaria. The agent does not announce these hours as new Ticqet bookings, includes them in updates and reminders, and tells the admin if they are open on Ticqet.
A3: Fill the yellow cells. One row per client per day. Times in 24-hour HH:MM (e.g. 17:00). Dates as DD/MM/YYYY (e.g. 01/09/2026). Add new clients in the empty rows.
A5: Client | B5: Facility | C5: Day | D5: Start | E5: End | F5: Hours | G5: Type | H5: From | I5: Until | J5: Status | K5: Check | L5: Notes
A6: Example Club | B6: Multi-Purpose Court | C6: Monday | D6: 0.70833333 | E6: 0.79166667 | F6: =IF(OR(D6="",E6="",E6<=D6),"",(E6-D6)*24) -> 2 | G6: Monthly | H6: 46296 | I6: 46326 | J6: =IF(A6="","",IF(AND(I6<>"",I6<TODAY()),"Ended",IF(AND(H6<>"",H6>TODAY()),"Not started",IF(OR(H6="",I6=""),"Dates missing","Active")))) -> Active | K6: =IF(A6="","",IF(OR(B6="",C6="",D6="",E6=""),"Missing details",IF(E6<=D6,"End must be after start",IF(SUMPRODUCT(($B$6:$B$30=B6)*($C$6:$C$30=C6)*($D$6:$D$30<E6)*($E$6:$E$30>D6))>1,"Overlaps another row","OK")))) -> OK | L6: Example row - replace with a real client.
A7: Example Club | B7: Multi-Purpose Court | C7: Wednesday | D7: 0.70833333 | E7: 0.79166667 | F7: =IF(OR(D7="",E7="",E7<=D7),"",(E7-D7)*24) -> 2 | G7: Monthly | H7: 46296 | I7: 46326 | J7: =IF(A7="","",IF(AND(I7<>"",I7<TODAY()),"Ended",IF(AND(H7<>"",H7>TODAY()),"Not started",IF(OR(H7="",I7=""),"Dates missing","Active")))) -> Active | K7: =IF(A7="","",IF(OR(B7="",C7="",D7="",E7=""),"Missing details",IF(E7<=D7,"End must be after start",IF(SUMPRODUCT(($B$6:$B$30=B7)*($C$6:$C$30=C7)*($D$6:$D$30<E7)*($E$6:$E$30>D7))>1,"Overlaps another row","OK")))) -> OK | L7: Example row.
A8: Example Company | B8: Multi-Purpose Court | C8: Tuesday | D8: 0.79166667 | E8: 0.875 | F8: =IF(OR(D8="",E8="",E8<=D8),"",(E8-D8)*24) -> 2 | G8: Monthly | H8: 46296 | I8: 46387 | J8: =IF(A8="","",IF(AND(I8<>"",I8<TODAY()),"Ended",IF(AND(H8<>"",H8>TODAY()),"Not started",IF(OR(H8="",I8=""),"Dates missing","Active")))) -> Active | K8: =IF(A8="","",IF(OR(B8="",C8="",D8="",E8=""),"Missing details",IF(E8<=D8,"End must be after start",IF(SUMPRODUCT(($B$6:$B$30=B8)*($C$6:$C$30=C8)*($D$6:$D$30<E8)*($E$6:$E$30>D8))>1,"Overlaps another row","OK")))) -> OK | L8: Example row.
F9: =IF(OR(D9="",E9="",E9<=D9),"",(E9-D9)*24) | J9: =IF(A9="","",IF(AND(I9<>"",I9<TODAY()),"Ended",IF(AND(H9<>"",H9>TODAY()),"Not started",IF(OR(H9="",I9=""),"Dates missing","Active")))) | K9: =IF(A9="","",IF(OR(B9="",C9="",D9="",E9=""),"Missing details",IF(E9<=D9,"End must be after start",IF(SUMPRODUCT(($B$6:$B$30=B9)*($C$6:$C$30=C9)*($D$6:$D$30<E9)*($E$6:$E$30>D9))>1,"Overlaps another row","OK"))))
F10: =IF(OR(D10="",E10="",E10<=D10),"",(E10-D10)*24) | J10: =IF(A10="","",IF(AND(I10<>"",I10<TODAY()),"Ended",IF(AND(H10<>"",H10>TODAY()),"Not started",IF(OR(H10="",I10=""),"Dates missing","Active")))) | K10: =IF(A10="","",IF(OR(B10="",C10="",D10="",E10=""),"Missing details",IF(E10<=D10,"End must be after start",IF(SUMPRODUCT(($B$6:$B$30=B10)*($C$6:$C$30=C10)*($D$6:$D$30<E10)*($E$6:$E$30>D10))>1,"Overlaps another row","OK"))))
F11: =IF(OR(D11="",E11="",E11<=D11),"",(E11-D11)*24) | J11: =IF(A11="","",IF(AND(I11<>"",I11<TODAY()),"Ended",IF(AND(H11<>"",H11>TODAY()),"Not started",IF(OR(H11="",I11=""),"Dates missing","Active")))) | K11: =IF(A11="","",IF(OR(B11="",C11="",D11="",E11=""),"Missing details",IF(E11<=D11,"End must be after start",IF(SUMPRODUCT(($B$6:$B$30=B11)*($C$6:$C$30=C11)*($D$6:$D$30<E11)*($E$6:$E$30>D11))>1,"Overlaps another row","OK"))))
F12: =IF(OR(D12="",E12="",E12<=D12),"",(E12-D12)*24) | J12: =IF(A12="","",IF(AND(I12<>"",I12<TODAY()),"Ended",IF(AND(H12<>"",H12>TODAY()),"Not started",IF(OR(H12="",I12=""),"Dates missing","Active")))) | K12: =IF(A12="","",IF(OR(B12="",C12="",D12="",E12=""),"Missing details",IF(E12<=D12,"End must be after start",IF(SUMPRODUCT(($B$6:$B$30=B12)*($C$6:$C$30=C12)*($D$6:$D$30<E12)*($E$6:$E$30>D12))>1,"Overlaps another row","OK"))))
F13: =IF(OR(D13="",E13="",E13<=D13),"",(E13-D13)*24) | J13: =IF(A13="","",IF(AND(I13<>"",I13<TODAY()),"Ended",IF(AND(H13<>"",H13>TODAY()),"Not started",IF(OR(H13="",I13=""),"Dates missing","Active")))) | K13: =IF(A13="","",IF(OR(B13="",C13="",D13="",E13=""),"Missing details",IF(E13<=D13,"End must be after start",IF(SUMPRODUCT(($B$6:$B$30=B13)*($C$6:$C$30=C13)*($D$6:$D$30<E13)*($E$6:$E$30>D13))>1,"Overlaps another row","OK"))))
F14: =IF(OR(D14="",E14="",E14<=D14),"",(E14-D14)*24) | J14: =IF(A14="","",IF(AND(I14<>"",I14<TODAY()),"Ended",IF(AND(H14<>"",H14>TODAY()),"Not started",IF(OR(H14="",I14=""),"Dates missing","Active")))) | K14: =IF(A14="","",IF(OR(B14="",C14="",D14="",E14=""),"Missing details",IF(E14<=D14,"End must be after start",IF(SUMPRODUCT(($B$6:$B$30=B14)*($C$6:$C$30=C14)*($D$6:$D$30<E14)*($E$6:$E$30>D14))>1,"Overlaps another row","OK"))))
F15: =IF(OR(D15="",E15="",E15<=D15),"",(E15-D15)*24) | J15: =IF(A15="","",IF(AND(I15<>"",I15<TODAY()),"Ended",IF(AND(H15<>"",H15>TODAY()),"Not started",IF(OR(H15="",I15=""),"Dates missing","Active")))) | K15: =IF(A15="","",IF(OR(B15="",C15="",D15="",E15=""),"Missing details",IF(E15<=D15,"End must be after start",IF(SUMPRODUCT(($B$6:$B$30=B15)*($C$6:$C$30=C15)*($D$6:$D$30<E15)*($E$6:$E$30>D15))>1,"Overlaps another row","OK"))))
F16: =IF(OR(D16="",E16="",E16<=D16),"",(E16-D16)*24) | J16: =IF(A16="","",IF(AND(I16<>"",I16<TODAY()),"Ended",IF(AND(H16<>"",H16>TODAY()),"Not started",IF(OR(H16="",I16=""),"Dates missing","Active")))) | K16: =IF(A16="","",IF(OR(B16="",C16="",D16="",E16=""),"Missing details",IF(E16<=D16,"End must be after start",IF(SUMPRODUCT(($B$6:$B$30=B16)*($C$6:$C$30=C16)*($D$6:$D$30<E16)*($E$6:$E$30>D16))>1,"Overlaps another row","OK"))))
F17: =IF(OR(D17="",E17="",E17<=D17),"",(E17-D17)*24) | J17: =IF(A17="","",IF(AND(I17<>"",I17<TODAY()),"Ended",IF(AND(H17<>"",H17>TODAY()),"Not started",IF(OR(H17="",I17=""),"Dates missing","Active")))) | K17: =IF(A17="","",IF(OR(B17="",C17="",D17="",E17=""),"Missing details",IF(E17<=D17,"End must be after start",IF(SUMPRODUCT(($B$6:$B$30=B17)*($C$6:$C$30=C17)*($D$6:$D$30<E17)*($E$6:$E$30>D17))>1,"Overlaps another row","OK"))))
F18: =IF(OR(D18="",E18="",E18<=D18),"",(E18-D18)*24) | J18: =IF(A18="","",IF(AND(I18<>"",I18<TODAY()),"Ended",IF(AND(H18<>"",H18>TODAY()),"Not started",IF(OR(H18="",I18=""),"Dates missing","Active")))) | K18: =IF(A18="","",IF(OR(B18="",C18="",D18="",E18=""),"Missing details",IF(E18<=D18,"End must be after start",IF(SUMPRODUCT(($B$6:$B$30=B18)*($C$6:$C$30=C18)*($D$6:$D$30<E18)*($E$6:$E$30>D18))>1,"Overlaps another row","OK"))))
F19: =IF(OR(D19="",E19="",E19<=D19),"",(E19-D19)*24) | J19: =IF(A19="","",IF(AND(I19<>"",I19<TODAY()),"Ended",IF(AND(H19<>"",H19>TODAY()),"Not started",IF(OR(H19="",I19=""),"Dates missing","Active")))) | K19: =IF(A19="","",IF(OR(B19="",C19="",D19="",E19=""),"Missing details",IF(E19<=D19,"End must be after start",IF(SUMPRODUCT(($B$6:$B$30=B19)*($C$6:$C$30=C19)*($D$6:$D$30<E19)*($E$6:$E$30>D19))>1,"Overlaps another row","OK"))))
F20: =IF(OR(D20="",E20="",E20<=D20),"",(E20-D20)*24) | J20: =IF(A20="","",IF(AND(I20<>"",I20<TODAY()),"Ended",IF(AND(H20<>"",H20>TODAY()),"Not started",IF(OR(H20="",I20=""),"Dates missing","Active")))) | K20: =IF(A20="","",IF(OR(B20="",C20="",D20="",E20=""),"Missing details",IF(E20<=D20,"End must be after start",IF(SUMPRODUCT(($B$6:$B$30=B20)*($C$6:$C$30=C20)*($D$6:$D$30<E20)*($E$6:$E$30>D20))>1,"Overlaps another row","OK"))))
... F30: =IF(OR(D30="",E30="",E30<=D30),"",(E30-D30)*24) | J30: =IF(A30="","",IF(AND(I30<>"",I30<TODAY()),"Ended",IF(AND(H30<>"",H30>TODAY()),"Not started",IF(OR(H30="",I30=""),"Dates missing","Active")))) | K30: =IF(A30="","",IF(OR(B30="",C30="",D30="",E30=""),"Missing details",IF(E30<=D30,"End must be after start",IF(SUMPRODUCT(($B$6:$B$30=B30)*($C$6:$C$30=C30)*($D$6:$D$30<E30)*($E$6:$E$30>D30))>1,"Overlaps another row","OK"))))
A32: Regular hours per week (clients not ended) | F32: =SUMIFS(F6:F30,J6:J30,"<>Ended",J6:J30,"<>Not started") -> 6

Sheet Week View
A1: Week View - regular clients
A2: Fills itself from the Regular Clients sheet. Rows match Ticqet's hourly slots (7:00 AM to 11:00 PM start times).
A3: Facility: | B3: Multi-Purpose Court
A5: TIME | B5: MONDAY | C5: TUESDAY | D5: WEDNESDAY | E5: THURSDAY | F5: FRIDAY | G5: SATURDAY | H5: SUNDAY
A6: 0.29166667 | B6: =IF(SUMPRODUCT(('Regular Clients'!$C$6:$C$30=B$5)*('Regular Clients'!$B$6:$B$30=$B$3)*('Regular Clients'!$D$6:$D$30<=$A6)*('Regular Clients'!$E$6:$E$30>$A6)*('Regular Clients'!$J$6:$J$30<>"Ended")*('Regular Clients'!$J$6:$J$30<>"Not started"))=0,"",IF(SUMPRODUCT(('Regular Clients'!$C$6:$C$30=B$5)*('Regular Clients'!$B$6:$B$30=$B$3)*('Regular Clients'!$D$6:$D$30<=$A6)*('Regular Clients'!$E$6:$E$30>$A6)*('Regular Clients'!$J$6:$J$30<>"Ended")*('Regular Clients'!$J$6:$J$30<>"Not started"))>1,"CLASH",INDEX('Regular Clients'!$A$6:$A$30,SUMPRODUCT(MAX(('Regular Clients'!$C$6:$C$30=B$5)*('Regular Clients'!$B$6:$B$30=$B$3)*('Regular Clients'!$D$6:$D$30<=$A6)*('Regular Clients'!$E$6:$E$30>$A6)*('Regular Clients'!$J$6:$J$30<>"Ended")*('Regular Clients'!$J$6:$J$30<>"Not started")*(ROW('Regular Clients'!$A$6:$A$30)-ROW('Regular Clients'!$A$6)+1)))))) | C6: =IF(SUMPRODUCT(('Regular Clients'!$C$6:$C$30=C$5)*('Regular Clients'!$B$6:$B$30=$B$3)*('Regular Clients'!$D$6:$D$30<=$A6)*('Regular Clients'!$E$6:$E$30>$A6)*('Regular Clients'!$J$6:$J$30<>"Ended")*('Regular Clients'!$J$6:$J$30<>"Not started"))=0,"",IF(SUMPRODUCT(('Regular Clients'!$C$6:$C$30=C$5)*('Regular Clients'!$B$6:$B$30=$B$3)*('Regular Clients'!$D$6:$D$30<=$A6)*('Regular Clients'!$E$6:$E$30>$A6)*('Regular Clients'!$J$6:$J$30<>"Ended")*('Regular Clients'!$J$6:$J$30<>"Not started"))>1,"CLASH",INDEX('Regular Clients'!$A$6:$A$30,SUMPRODUCT(MAX(('Regular Clients'!$C$6:$C$30=C$5)*('Regular Clients'!$B$6:$B$30=$B$3)*('Regular Clients'!$D$6:$D$30<=$A6)*('Regular Clients'!$E$6:$E$30>$A6)*('Regular Clients'!$J$6:$J$30<>"Ended")*('Regular Clients'!$J$6:$J$30<>"Not started")*(ROW('Regular Clients'!$A$6:$A$30)-ROW('Regular Clients'!$A$6)+1)))))) | D6: =IF(SUMPRODUCT(('Regular Clients'!$C$6:$C$30=D$5)*('Regular Clients'!$B$6:$B$30=$B$3)*('Regular Clients'!$D$6:$D$30<=$A6)*('Regular Clients'!$E$6:$E$30>$A6)*('Regular Clients'!$J$6:$J$30<>"Ended")*('Regular Clients'!$J$6:$J$30<>"Not started"))=0,"",IF(SUMPRODUCT(('Regular Clients'!$C$6:$C$30=D$5)*('Regular Clients'!$B$6:$B$30=$B$3)*('Regular Clients'!$D$6:$D$30<=$A6)*('Regular Clients'!$E$6:$E$30>$A6)*('Regular Clients'!$J$6:$J$30<>"Ended")*('Regular Clients'!$J$6:$J$30<>"Not started"))>1,"CLASH",INDEX('Regular Clients'!$A$6:$A$30,SUMPRODUCT(MAX(('Regular Clients'!$C$6:$C$30=D$5)*('Regular Clients'!$B$6:$B$30=$B$3)*('Regular Clients'!$D$6:$D$30<=$A6)*('Regular Clients'!$E$6:$E$30>$A6)*('Regular Clients'!$J$6:$J$30<>"Ended")*('Regular Clients'!$J$6:$J$30<>"Not started")*(ROW('Regular Clients'!$A$6:$A$30)-ROW('Regular Clients'!$A$6)+1)))))) | E6: =IF(SUMPRODUCT(('Regular Clients'!$C$6:$C$30=E$5)*('Regular Clients'!$B$6:$B$30=$B$3)*('Regular Clients'!$D$6:$D$30<=$A6)*('Regular Clients'!$E$6:$E$30>$A6)*('Regular Clients'!$J$6:$J$30<>"Ended")*('Regular Clients'!$J$6:$J$30<>"Not started"))=0,"",IF(SUMPRODUCT(('Regular Clients'!$C$6:$C$30=E$5)*('Regular Clients'!$B$6:$B$30=$B$3)*('Regular Clients'!$D$6:$D$30<=$A6)*('Regular Clients'!$E$6:$E$30>$A6)*('Regular Clients'!$J$6:$J$30<>"Ended")*('Regular Clients'!$J$6:$J$30<>"Not started"))>1,"CLASH",INDEX('Regular Clients'!$A$6:$A$30,SUMPRODUCT(MAX(('Regular Clients'!$C$6:$C$30=E$5)*('Regular Clients'!$B$6:$B$30=$B$3)*('Regular Clients'!$D$6:$D$30<=$A6)*('Regular Clients'!$E$6:$E$30>$A6)*('Regular Clients'!$J$6:$J$30<>"Ended")*('Regular Clients'!$J$6:$J$30<>"Not started")*(ROW('Regular Clients'!$A$6:$A$30)-ROW('Regular Clients'!$A$6)+1)))))) | F6: =IF(SUMPRODUCT(('Regular Clients'!$C$6:$C$30=F$5)*('Regular Clients'!$B$6:$B$30=$B$3)*('Regular Clients'!$D$6:$D$30<=$A6)*('Regular Clients'!$E$6:$E$30>$A6)*('Regular Clients'!$J$6:$J$30<>"Ended")*('Regular Clients'!$J$6:$J$30<>"Not started"))=0,"",IF(SUMPRODUCT(('Regular Clients'!$C$6:$C$30=F$5)*('Regular Clients'!$B$6:$B$30=$B$3)*('Regular Clients'!$D$6:$D$30<=$A6)*('Regular Clients'!$E$6:$E$30>$A6)*('Regular Clients'!$J$6:$J$30<>"Ended")*('Regular Clients'!$J$6:$J$30<>"Not started"))>1,"CLASH",INDEX('Regular Clients'!$A$6:$A$30,SUMPRODUCT(MAX(('Regular Clients'!$C$6:$C$30=F$5)*('Regular Clients'!$B$6:$B$30=$B$3)*('Regular Clients'!$D$6:$D$30<=$A6)*('Regular Clients'!$E$6:$E$30>$A6)*('Regular Clients'!$J$6:$J$30<>"Ended")*('Regular Clients'!$J$6:$J$30<>"Not started")*(ROW('Regular Clients'!$A$6:$A$30)-ROW('Regular Clients'!$A$6)+1)))))) | G6: =IF(SUMPRODUCT(('Regular Clients'!$C$6:$C$30=G$5)*('Regular Clients'!$B$6:$B$30=$B$3)*('Regular Clients'!$D$6:$D$30<=$A6)*('Regular Clients'!$E$6:$E$30>$A6)*('Regular Clients'!$J$6:$J$30<>"Ended")*('Regular Clients'!$J$6:$J$30<>"Not started"))=0,"",IF(SUMPRODUCT(('Regular Clients'!$C$6:$C$30=G$5)*('Regular Clients'!$B$6:$B$30=$B$3)*('Regular Clients'!$D$6:$D$30<=$A6)*('Regular Clients'!$E$6:$E$30>$A6)*('Regular Clients'!$J$6:$J$30<>"Ended")*('Regular Clients'!$J$6:$J$30<>"Not started"))>1,"CLASH",INDEX('Regular Clients'!$A$6:$A$30,SUMPRODUCT(MAX(('Regular Clients'!$C$6:$C$30=G$5)*('Regular Clients'!$B$6:$B$30=$B$3)*('Regular Clients'!$D$6:$D$30<=$A6)*('Regular Clients'!$E$6:$E$30>$A6)*('Regular Clients'!$J$6:$J$30<>"Ended")*('Regular Clients'!$J$6:$J$30<>"Not started")*(ROW('Regular Clients'!$A$6:$A$30)-ROW('Regular Clients'!$A$6)+1)))))) | H6: =IF(SUMPRODUCT(('Regular Clients'!$C$6:$C$30=H$5)*('Regular Clients'!$B$6:$B$30=$B$3)*('Regular Clients'!$D$6:$D$30<=$A6)*('Regular Clients'!$E$6:$E$30>$A6)*('Regular Clients'!$J$6:$J$30<>"Ended")*('Regular Clients'!$J$6:$J$30<>"Not started"))=0,"",IF(SUMPRODUCT(('Regular Clients'!$C$6:$C$30=H$5)*('Regular Clients'!$B$6:$B$30=$B$3)*('Regular Clients'!$D$6:$D$30<=$A6)*('Regular Clients'!$E$6:$E$30>$A6)*('Regular Clients'!$J$6:$J$30<>"Ended")*('Regular Clients'!$J$6:$J$30<>"Not started"))>1,"CLASH",INDEX('Regular Clients'!$A$6:$A$30,SUMPRODUCT(MAX(('Regular Clients'!$C$6:$C$30=H$5)*('Regular Clients'!$B$6:$B$30=$B$3)*('Regular Clients'!$D$6:$D$30<=$A6)*('Regular Clients'!$E$6:$E$30>$A6)*('Regular Clients'!$J$6:$J$30<>"Ended")*('Regular Clients'!$J$6:$J$30<>"Not started")*(ROW('Regular Clients'!$A$6:$A$30)-ROW('Regular Clients'!$A$6)+1))))))
A7: 0.33333333 | B7: =IF(SUMPRODUCT(('Regular Clients'!$C$6:$C$30=B$5)*('Regular Clients'!$B$6:$B$30=$B$3)*('Regular Clients'!$D$6:$D$30<=$A7)*('Regular Clients'!$E$6:$E$30>$A7)*('Regular Clients'!$J$6:$J$30<>"Ended")*('Regular Clients'!$J$6:$J$30<>"Not started"))=0,"",IF(SUMPRODUCT(('Regular Clients'!$C$6:$C$30=B$5)*('Regular Clients'!$B$6:$B$30=$B$3)*('Regular Clients'!$D$6:$D$30<=$A7)*('Regular Clients'!$E$6:$E$30>$A7)*('Regular Clients'!$J$6:$J$30<>"Ended")*('Regular Clients'!$J$6:$J$30<>"Not started"))>1,"CLASH",INDEX('Regular Clients'!$A$6:$A$30,SUMPRODUCT(MAX(('Regular Clients'!$C$6:$C$30=B$5)*('Regular Clients'!$B$6:$B$30=$B$3)*('Regular Clients'!$D$6:$D$30<=$A7)*('Regular Clients'!$E$6:$E$30>$A7)*('Regular Clients'!$J$6:$J$30<>"Ended")*('Regular Clients'!$J$6:$J$30<>"Not started")*(ROW('Regular Clients'!$A$6:$A$30)-ROW('Regular Clients'!$A$6)+1)))))) | C7: =IF(SUMPRODUCT(('Regular Clients'!$C$6:$C$30=C$5)*('Regular Clients'!$B$6:$B$30=$B$3)*('Regular Clients'!$D$6:$D$30<=$A7)*('Regular Clients'!$E$6:$E$30>$A7)*('Regular Clients'!$J$6:$J$30<>"Ended")*('Regular Clients'!$J$6:$J$30<>"Not started"))=0,"",IF(SUMPRODUCT(('Regular Clients'!$C$6:$C$30=C$5)*('Regular Clients'!$B$6:$B$30=$B$3)*('Regular Clients'!$D$6:$D$30<=$A7)*('Regular Clients'!$E$6:$E$30>$A7)*('Regular Clients'!$J$6:$J$30<>"Ended")*('Regular Clients'!$J$6:$J$30<>"Not started"))>1,"CLASH",INDEX('Regular Clients'!$A$6:$A$30,SUMPRODUCT(MAX(('Regular Clients'!$C$6:$C$30=C$5)*('Regular Clients'!$B$6:$B$30=$B$3)*('Regular Clients'!$D$6:$D$30<=$A7)*('Regular Clients'!$E$6:$E$30>$A7)*('Regular Clients'!$J$6:$J$30<>"Ended")*('Regular Clients'!$J$6:$J$30<>"Not started")*(ROW('Regular Clients'!$A$6:$A$30)-ROW('Regular Clients'!$A$6)+1)))))) | D7: =IF(SUMPRODUCT(('Regular Clients'!$C$6:$C$30=D$5)*('Regular Clients'!$B$6:$B$30=$B$3)*('Regular Clients'!$D$6:$D$30<=$A7)*('Regular Clients'!$E$6:$E$30>$A7)*('Regular Clients'!$J$6:$J$30<>"Ended")*('Regular Clients'!$J$6:$J$30<>"Not started"))=0,"",IF(SUMPRODUCT(('Regular Clients'!$C$6:$C$30=D$5)*('Regular Clients'!$B$6:$B$30=$B$3)*('Regular Clients'!$D$6:$D$30<=$A7)*('Regular Clients'!$E$6:$E$30>$A7)*('Regular Clients'!$J$6:$J$30<>"Ended")*('Regular Clients'!$J$6:$J$30<>"Not started"))>1,"CLASH",INDEX('Regular Clients'!$A$6:$A$30,SUMPRODUCT(MAX(('Regular Clients'!$C$6:$C$30=D$5)*('Regular Clients'!$B$6:$B$30=$B$3)*('Regular Clients'!$D$6:$D$30<=$A7)*('Regular Clients'!$E$6:$E$30>$A7)*('Regular Clients'!$J$6:$J$30<>"Ended")*('Regular Clients'!$J$6:$J$30<>"Not started")*(ROW('Regular Clients'!$A$6:$A$30)-ROW('Regular Clients'!$A$6)+1)))))) | E7: =IF(SUMPRODUCT(('Regular Clients'!$C$6:$C$30=E$5)*('Regular Clients'!$B$6:$B$30=$B$3)*('Regular Clients'!$D$6:$D$30<=$A7)*('Regular Clients'!$E$6:$E$30>$A7)*('Regular Clients'!$J$6:$J$30<>"Ended")*('Regular Clients'!$J$6:$J$30<>"Not started"))=0,"",IF(SUMPRODUCT(('Regular Clients'!$C$6:$C$30=E$5)*('Regular Clients'!$B$6:$B$30=$B$3)*('Regular Clients'!$D$6:$D$30<=$A7)*('Regular Clients'!$E$6:$E$30>$A7)*('Regular Clients'!$J$6:$J$30<>"Ended")*('Regular Clients'!$J$6:$J$30<>"Not started"))>1,"CLASH",INDEX('Regular Clients'!$A$6:$A$30,SUMPRODUCT(MAX(('Regular Clients'!$C$6:$C$30=E$5)*('Regular Clients'!$B$6:$B$30=$B$3)*('Regular Clients'!$D$6:$D$30<=$A7)*('Regular Clients'!$E$6:$E$30>$A7)*('Regular Clients'!$J$6:$J$30<>"Ended")*('Regular Clients'!$J$6:$J$30<>"Not started")*(ROW('Regular Clients'!$A$6:$A$30)-ROW('Regular Clients'!$A$6)+1)))))) | F7: =IF(SUMPRODUCT(('Regular Clients'!$C$6:$C$30=F$5)*('Regular Clients'!$B$6:$B$30=$B$3)*('Regular Clients'!$D$6:$D$30<=$A7)*('Regular Clients'!$E$6:$E$30>$A7)*('Regular Clients'!$J$6:$J$30<>"Ended")*('Regular Clients'!$J$6:$J$30<>"Not started"))=0,"",IF(SUMPRODUCT(('Regular Clients'!$C$6:$C$30=F$5)*('Regular Clients'!$B$6:$B$30=$B$3)*('Regular Clients'!$D$6:$D$30<=$A7)*('Regular Clients'!$E$6:$E$30>$A7)*('Regular Clients'!$J$6:$J$30<>"Ended")*('Regular Clients'!$J$6:$J$30<>"Not started"))>1,"CLASH",INDEX('Regular Clients'!$A$6:$A$30,SUMPRODUCT(MAX(('Regular Clients'!$C$6:$C$30=F$5)*('Regular Clients'!$B$6:$B$30=$B$3)*('Regular Clients'!$D$6:$D$30<=$A7)*('Regular Clients'!$E$6:$E$30>$A7)*('Regular Clients'!$J$6:$J$30<>"Ended")*('Regular Clients'!$J$6:$J$30<>"Not started")*(ROW('Regular Clients'!$A$6:$A$30)-ROW('Regular Clients'!$A$6)+1)))))) | G7: =IF(SUMPRODUCT(('Regular Clients'!$C$6:$C$30=G$5)*('Regular Clients'!$B$6:$B$30=$B$3)*('Regular Clients'!$D$6:$D$30<=$A7)*('Regular Clients'!$E$6:$E$30>$A7)*('Regular Clients'!$J$6:$J$30<>"Ended")*('Regular Clients'!$J$6:$J$30<>"Not started"))=0,"",IF(SUMPRODUCT(('Regular Clients'!$C$6:$C$30=G$5)*('Regular Clients'!$B$6:$B$30=$B$3)*('Regular Clients'!$D$6:$D$30<=$A7)*('Regular Clients'!$E$6:$E$30>$A7)*('Regular Clients'!$J$6:$J$30<>"Ended")*('Regular Clients'!$J$6:$J$30<>"Not started"))>1,"CLASH",INDEX('Regular Clients'!$A$6:$A$30,SUMPRODUCT(MAX(('Regular Clients'!$C$6:$C$30=G$5)*('Regular Clients'!$B$6:$B$30=$B$3)*('Regular Clients'!$D$6:$D$30<=$A7)*('Regular Clients'!$E$6:$E$30>$A7)*('Regular Clients'!$J$6:$J$30<>"Ended")*('Regular Clients'!$J$6:$J$30<>"Not started")*(ROW('Regular Clients'!$A$6:$A$30)-ROW('Regular Clients'!$A$6)+1)))))) | H7: =IF(SUMPRODUCT(('Regular Clients'!$C$6:$C$30=H$5)*('Regular Clients'!$B$6:$B$30=$B$3)*('Regular Clients'!$D$6:$D$30<=$A7)*('Regular Clients'!$E$6:$E$30>$A7)*('Regular Clients'!$J$6:$J$30<>"Ended")*('Regular Clients'!$J$6:$J$30<>"Not started"))=0,"",IF(SUMPRODUCT(('Regular Clients'!$C$6:$C$30=H$5)*('Regular Clients'!$B$6:$B$30=$B$3)*('Regular Clients'!$D$6:$D$30<=$A7)*('Regular Clients'!$E$6:$E$30>$A7)*('Regular Clients'!$J$6:$J$30<>"Ended")*('Regular Clients'!$J$6:$J$30<>"Not started"))>1,"CLASH",INDEX('Regular Clients'!$A$6:$A$30,SUMPRODUCT(MAX(('Regular Clients'!$C$6:$C$30=H$5)*('Regular Clients'!$B$6:$B$30=$B$3)*('Regular Clients'!$D$6:$D$30<=$A7)*('Regular Clients'!$E$6:$E$30>$A7)*('Regular Clients'!$J$6:$J$30<>"Ended")*('Regular Clients'!$J$6:$J$30<>"Not started")*(ROW('Regular Clients'!$A$6:$A$30)-ROW('Regular Clients'!$A$6)+1))))))
A8: 0.375 | B8: =IF(SUMPRODUCT(('Regular Clients'!$C$6:$C$30=B$5)*('Regular Clients'!$B$6:$B$30=$B$3)*('Regular Clients'!$D$6:$D$30<=$A8)*('Regular Clients'!$E$6:$E$30>$A8)*('Regular Clients'!$J$6:$J$30<>"Ended")*('Regular Clients'!$J$6:$J$30<>"Not started"))=0,"",IF(SUMPRODUCT(('Regular Clients'!$C$6:$C$30=B$5)*('Regular Clients'!$B$6:$B$30=$B$3)*('Regular Clients'!$D$6:$D$30<=$A8)*('Regular Clients'!$E$6:$E$30>$A8)*('Regular Clients'!$J$6:$J$30<>"Ended")*('Regular Clients'!$J$6:$J$30<>"Not started"))>1,"CLASH",INDEX('Regular Clients'!$A$6:$A$30,SUMPRODUCT(MAX(('Regular Clients'!$C$6:$C$30=B$5)*('Regular Clients'!$B$6:$B$30=$B$3)*('Regular Clients'!$D$6:$D$30<=$A8)*('Regular Clients'!$E$6:$E$30>$A8)*('Regular Clients'!$J$6:$J$30<>"Ended")*('Regular Clients'!$J$6:$J$30<>"Not started")*(ROW('Regular Clients'!$A$6:$A$30)-ROW('Regular Clients'!$A$6)+1)))))) | C8: =IF(SUMPRODUCT(('Regular Clients'!$C$6:$C$30=C$5)*('Regular Clients'!$B$6:$B$30=$B$3)*('Regular Clients'!$D$6:$D$30<=$A8)*('Regular Clients'!$E$6:$E$30>$A8)*('Regular Clients'!$J$6:$J$30<>"Ended")*('Regular Clients'!$J$6:$J$30<>"Not started"))=0,"",IF(SUMPRODUCT(('Regular Clients'!$C$6:$C$30=C$5)*('Regular Clients'!$B$6:$B$30=$B$3)*('Regular Clients'!$D$6:$D$30<=$A8)*('Regular Clients'!$E$6:$E$30>$A8)*('Regular Clients'!$J$6:$J$30<>"Ended")*('Regular Clients'!$J$6:$J$30<>"Not started"))>1,"CLASH",INDEX('Regular Clients'!$A$6:$A$30,SUMPRODUCT(MAX(('Regular Clients'!$C$6:$C$30=C$5)*('Regular Clients'!$B$6:$B$30=$B$3)*('Regular Clients'!$D$6:$D$30<=$A8)*('Regular Clients'!$E$6:$E$30>$A8)*('Regular Clients'!$J$6:$J$30<>"Ended")*('Regular Clients'!$J$6:$J$30<>"Not started")*(ROW('Regular Clients'!$A$6:$A$30)-ROW('Regular Clients'!$A$6)+1)))))) | D8: =IF(SUMPRODUCT(('Regular Clients'!$C$6:$C$30=D$5)*('Regular Clients'!$B$6:$B$30=$B$3)*('Regular Clients'!$D$6:$D$30<=$A8)*('Regular Clients'!$E$6:$E$30>$A8)*('Regular Clients'!$J$6:$J$30<>"Ended")*('Regular Clients'!$J$6:$J$30<>"Not started"))=0,"",IF(SUMPRODUCT(('Regular Clients'!$C$6:$C$30=D$5)*('Regular Clients'!$B$6:$B$30=$B$3)*('Regular Clients'!$D$6:$D$30<=$A8)*('Regular Clients'!$E$6:$E$30>$A8)*('Regular Clients'!$J$6:$J$30<>"Ended")*('Regular Clients'!$J$6:$J$30<>"Not started"))>1,"CLASH",INDEX('Regular Clients'!$A$6:$A$30,SUMPRODUCT(MAX(('Regular Clients'!$C$6:$C$30=D$5)*('Regular Clients'!$B$6:$B$30=$B$3)*('Regular Clients'!$D$6:$D$30<=$A8)*('Regular Clients'!$E$6:$E$30>$A8)*('Regular Clients'!$J$6:$J$30<>"Ended")*('Regular Clients'!$J$6:$J$30<>"Not started")*(ROW('Regular Clients'!$A$6:$A$30)-ROW('Regular Clients'!$A$6)+1)))))) | E8: =IF(SUMPRODUCT(('Regular Clients'!$C$6:$C$30=E$5)*('Regular Clients'!$B$6:$B$30=$B$3)*('Regular Clients'!$D$6:$D$30<=$A8)*('Regular Clients'!$E$6:$E$30>$A8)*('Regular Clients'!$J$6:$J$30<>"Ended")*('Regular Clients'!$J$6:$J$30<>"Not started"))=0,"",IF(SUMPRODUCT(('Regular Clients'!$C$6:$C$30=E$5)*('Regular Clients'!$B$6:$B$30=$B$3)*('Regular Clients'!$D$6:$D$30<=$A8)*('Regular Clients'!$E$6:$E$30>$A8)*('Regular Clients'!$J$6:$J$30<>"Ended")*('Regular Clients'!$J$6:$J$30<>"Not started"))>1,"CLASH",INDEX('Regular Clients'!$A$6:$A$30,SUMPRODUCT(MAX(('Regular Clients'!$C$6:$C$30=E$5)*('Regular Clients'!$B$6:$B$30=$B$3)*('Regular Clients'!$D$6:$D$30<=$A8)*('Regular Clients'!$E$6:$E$30>$A8)*('Regular Clients'!$J$6:$J$30<>"Ended")*('Regular Clients'!$J$6:$J$30<>"Not started")*(ROW('Regular Clients'!$A$6:$A$30)-ROW('Regular Clients'!$A$6)+1)))))) | F8: =IF(SUMPRODUCT(('Regular Clients'!$C$6:$C$30=F$5)*('Regular Clients'!$B$6:$B$30=$B$3)*('Regular Clients'!$D$6:$D$30<=$A8)*('Regular Clients'!$E$6:$E$30>$A8)*('Regular Clients'!$J$6:$J$30<>"Ended")*('Regular Clients'!$J$6:$J$30<>"Not started"))=0,"",IF(SUMPRODUCT(('Regular Clients'!$C$6:$C$30=F$5)*('Regular Clients'!$B$6:$B$30=$B$3)*('Regular Clients'!$D$6:$D$30<=$A8)*('Regular Clients'!$E$6:$E$30>$A8)*('Regular Clients'!$J$6:$J$30<>"Ended")*('Regular Clients'!$J$6:$J$30<>"Not started"))>1,"CLASH",INDEX('Regular Clients'!$A$6:$A$30,SUMPRODUCT(MAX(('Regular Clients'!$C$6:$C$30=F$5)*('Regular Clients'!$B$6:$B$30=$B$3)*('Regular Clients'!$D$6:$D$30<=$A8)*('Regular Clients'!$E$6:$E$30>$A8)*('Regular Clients'!$J$6:$J$30<>"Ended")*('Regular Clients'!$J$6:$J$30<>"Not started")*(ROW('Regular Clients'!$A$6:$A$30)-ROW('Regular Clients'!$A$6)+1)))))) | G8: =IF(SUMPRODUCT(('Regular Clients'!$C$6:$C$30=G$5)*('Regular Clients'!$B$6:$B$30=$B$3)*('Regular Clients'!$D$6:$D$30<=$A8)*('Regular Clients'!$E$6:$E$30>$A8)*('Regular Clients'!$J$6:$J$30<>"Ended")*('Regular Clients'!$J$6:$J$30<>"Not started"))=0,"",IF(SUMPRODUCT(('Regular Clients'!$C$6:$C$30=G$5)*('Regular Clients'!$B$6:$B$30=$B$3)*('Regular Clients'!$D$6:$D$30<=$A8)*('Regular Clients'!$E$6:$E$30>$A8)*('Regular Clients'!$J$6:$J$30<>"Ended")*('Regular Clients'!$J$6:$J$30<>"Not started"))>1,"CLASH",INDEX('Regular Clients'!$A$6:$A$30,SUMPRODUCT(MAX(('Regular Clients'!$C$6:$C$30=G$5)*('Regular Clients'!$B$6:$B$30=$B$3)*('Regular Clients'!$D$6:$D$30<=$A8)*('Regular Clients'!$E$6:$E$30>$A8)*('Regular Clients'!$J$6:$J$30<>"Ended")*('Regular Clients'!$J$6:$J$30<>"Not started")*(ROW('Regular Clients'!$A$6:$A$30)-ROW('Regular Clients'!$A$6)+1)))))) | H8: =IF(SUMPRODUCT(('Regular Clients'!$C$6:$C$30=H$5)*('Regular Clients'!$B$6:$B$30=$B$3)*('Regular Clients'!$D$6:$D$30<=$A8)*('Regular Clients'!$E$6:$E$30>$A8)*('Regular Clients'!$J$6:$J$30<>"Ended")*('Regular Clients'!$J$6:$J$30<>"Not started"))=0,"",IF(SUMPRODUCT(('Regular Clients'!$C$6:$C$30=H$5)*('Regular Clients'!$B$6:$B$30=$B$3)*('Regular Clients'!$D$6:$D$30<=$A8)*('Regular Clients'!$E$6:$E$30>$A8)*('Regular Clients'!$J$6:$J$30<>"Ended")*('Regular Clients'!$J$6:$J$30<>"Not started"))>1,"CLASH",INDEX('Regular Clients'!$A$6:$A$30,SUMPRODUCT(MAX(('Regular Clients'!$C$6:$C$30=H$5)*('Regular Clients'!$B$6:$B$30=$B$3)*('Regular Clients'!$D$6:$D$30<=$A8)*('Regular Clients'!$E$6:$E$30>$A8)*('Regular Clients'!$J$6:$J$30<>"Ended")*('Regular Clients'!$J$6:$J$30<>"Not started")*(ROW('Regular Clients'!$A$6:$A$30)-ROW('Regular Clients'!$A$6)+1))))))
A9: 0.41666667 | B9: =IF(SUMPRODUCT(('Regular Clients'!$C$6:$C$30=B$5)*('Regular Clients'!$B$6:$B$30=$B$3)*('Regular Clients'!$D$6:$D$30<=$A9)*('Regular Clients'!$E$6:$E$30>$A9)*('Regular Clients'!$J$6:$J$30<>"Ended")*('Regular Clients'!$J$6:$J$30<>"Not started"))=0,"",IF(SUMPRODUCT(('Regular Clients'!$C$6:$C$30=B$5)*('Regular Clients'!$B$6:$B$30=$B$3)*('Regular Clients'!$D$6:$D$30<=$A9)*('Regular Clients'!$E$6:$E$30>$A9)*('Regular Clients'!$J$6:$J$30<>"Ended")*('Regular Clients'!$J$6:$J$30<>"Not started"))>1,"CLASH",INDEX('Regular Clients'!$A$6:$A$30,SUMPRODUCT(MAX(('Regular Clients'!$C$6:$C$30=B$5)*('Regular Clients'!$B$6:$B$30=$B$3)*('Regular Clients'!$D$6:$D$30<=$A9)*('Regular Clients'!$E$6:$E$30>$A9)*('Regular Clients'!$J$6:$J$30<>"Ended")*('Regular Clients'!$J$6:$J$30<>"Not started")*(ROW('Regular Clients'!$A$6:$A$30)-ROW('Regular Clients'!$A$6)+1)))))) | C9: =IF(SUMPRODUCT(('Regular Clients'!$C$6:$C$30=C$5)*('Regular Clients'!$B$6:$B$30=$B$3)*('Regular Clients'!$D$6:$D$30<=$A9)*('Regular Clients'!$E$6:$E$30>$A9)*('Regular Clients'!$J$6:$J$30<>"Ended")*('Regular Clients'!$J$6:$J$30<>"Not started"))=0,"",IF(SUMPRODUCT(('Regular Clients'!$C$6:$C$30=C$5)*('Regular Clients'!$B$6:$B$30=$B$3)*('Regular Clients'!$D$6:$D$30<=$A9)*('Regular Clients'!$E$6:$E$30>$A9)*('Regular Clients'!$J$6:$J$30<>"Ended")*('Regular Clients'!$J$6:$J$30<>"Not started"))>1,"CLASH",INDEX('Regular Clients'!$A$6:$A$30,SUMPRODUCT(MAX(('Regular Clients'!$C$6:$C$30=C$5)*('Regular Clients'!$B$6:$B$30=$B$3)*('Regular Clients'!$D$6:$D$30<=$A9)*('Regular Clients'!$E$6:$E$30>$A9)*('Regular Clients'!$J$6:$J$30<>"Ended")*('Regular Clients'!$J$6:$J$30<>"Not started")*(ROW('Regular Clients'!$A$6:$A$30)-ROW('Regular Clients'!$A$6)+1)))))) | D9: =IF(SUMPRODUCT(('Regular Clients'!$C$6:$C$30=D$5)*('Regular Clients'!$B$6:$B$30=$B$3)*('Regular Clients'!$D$6:$D$30<=$A9)*('Regular Clients'!$E$6:$E$30>$A9)*('Regular Clients'!$J$6:$J$30<>"Ended")*('Regular Clients'!$J$6:$J$30<>"Not started"))=0,"",IF(SUMPRODUCT(('Regular Clients'!$C$6:$C$30=D$5)*('Regular Clients'!$B$6:$B$30=$B$3)*('Regular Clients'!$D$6:$D$30<=$A9)*('Regular Clients'!$E$6:$E$30>$A9)*('Regular Clients'!$J$6:$J$30<>"Ended")*('Regular Clients'!$J$6:$J$30<>"Not started"))>1,"CLASH",INDEX('Regular Clients'!$A$6:$A$30,SUMPRODUCT(MAX(('Regular Clients'!$C$6:$C$30=D$5)*('Regular Clients'!$B$6:$B$30=$B$3)*('Regular Clients'!$D$6:$D$30<=$A9)*('Regular Clients'!$E$6:$E$30>$A9)*('Regular Clients'!$J$6:$J$30<>"Ended")*('Regular Clients'!$J$6:$J$30<>"Not started")*(ROW('Regular Clients'!$A$6:$A$30)-ROW('Regular Clients'!$A$6)+1)))))) | E9: =IF(SUMPRODUCT(('Regular Clients'!$C$6:$C$30=E$5)*('Regular Clients'!$B$6:$B$30=$B$3)*('Regular Clients'!$D$6:$D$30<=$A9)*('Regular Clients'!$E$6:$E$30>$A9)*('Regular Clients'!$J$6:$J$30<>"Ended")*('Regular Clients'!$J$6:$J$30<>"Not started"))=0,"",IF(SUMPRODUCT(('Regular Clients'!$C$6:$C$30=E$5)*('Regular Clients'!$B$6:$B$30=$B$3)*('Regular Clients'!$D$6:$D$30<=$A9)*('Regular Clients'!$E$6:$E$30>$A9)*('Regular Clients'!$J$6:$J$30<>"Ended")*('Regular Clients'!$J$6:$J$30<>"Not started"))>1,"CLASH",INDEX('Regular Clients'!$A$6:$A$30,SUMPRODUCT(MAX(('Regular Clients'!$C$6:$C$30=E$5)*('Regular Clients'!$B$6:$B$30=$B$3)*('Regular Clients'!$D$6:$D$30<=$A9)*('Regular Clients'!$E$6:$E$30>$A9)*('Regular Clients'!$J$6:$J$30<>"Ended")*('Regular Clients'!$J$6:$J$30<>"Not started")*(ROW('Regular Clients'!$A$6:$A$30)-ROW('Regular Clients'!$A$6)+1)))))) | F9: =IF(SUMPRODUCT(('Regular Clients'!$C$6:$C$30=F$5)*('Regular Clients'!$B$6:$B$30=$B$3)*('Regular Clients'!$D$6:$D$30<=$A9)*('Regular Clients'!$E$6:$E$30>$A9)*('Regular Clients'!$J$6:$J$30<>"Ended")*('Regular Clients'!$J$6:$J$30<>"Not started"))=0,"",IF(SUMPRODUCT(('Regular Clients'!$C$6:$C$30=F$5)*('Regular Clients'!$B$6:$B$30=$B$3)*('Regular Clients'!$D$6:$D$30<=$A9)*('Regular Clients'!$E$6:$E$30>$A9)*('Regular Clients'!$J$6:$J$30<>"Ended")*('Regular Clients'!$J$6:$J$30<>"Not started"))>1,"CLASH",INDEX('Regular Clients'!$A$6:$A$30,SUMPRODUCT(MAX(('Regular Clients'!$C$6:$C$30=F$5)*('Regular Clients'!$B$6:$B$30=$B$3)*('Regular Clients'!$D$6:$D$30<=$A9)*('Regular Clients'!$E$6:$E$30>$A9)*('Regular Clients'!$J$6:$J$30<>"Ended")*('Regular Clients'!$J$6:$J$30<>"Not started")*(ROW('Regular Clients'!$A$6:$A$30)-ROW('Regular Clients'!$A$6)+1)))))) | G9: =IF(SUMPRODUCT(('Regular Clients'!$C$6:$C$30=G$5)*('Regular Clients'!$B$6:$B$30=$B$3)*('Regular Clients'!$D$6:$D$30<=$A9)*('Regular Clients'!$E$6:$E$30>$A9)*('Regular Clients'!$J$6:$J$30<>"Ended")*('Regular Clients'!$J$6:$J$30<>"Not started"))=0,"",IF(SUMPRODUCT(('Regular Clients'!$C$6:$C$30=G$5)*('Regular Clients'!$B$6:$B$30=$B$3)*('Regular Clients'!$D$6:$D$30<=$A9)*('Regular Clients'!$E$6:$E$30>$A9)*('Regular Clients'!$J$6:$J$30<>"Ended")*('Regular Clients'!$J$6:$J$30<>"Not started"))>1,"CLASH",INDEX('Regular Clients'!$A$6:$A$30,SUMPRODUCT(MAX(('Regular Clients'!$C$6:$C$30=G$5)*('Regular Clients'!$B$6:$B$30=$B$3)*('Regular Clients'!$D$6:$D$30<=$A9)*('Regular Clients'!$E$6:$E$30>$A9)*('Regular Clients'!$J$6:$J$30<>"Ended")*('Regular Clients'!$J$6:$J$30<>"Not started")*(ROW('Regular Clients'!$A$6:$A$30)-ROW('Regular Clients'!$A$6)+1)))))) | H9: =IF(SUMPRODUCT(('Regular Clients'!$C$6:$C$30=H$5)*('Regular Clients'!$B$6:$B$30=$B$3)*('Regular Clients'!$D$6:$D$30<=$A9)*('Regular Clients'!$E$6:$E$30>$A9)*('Regular Clients'!$J$6:$J$30<>"Ended")*('Regular Clients'!$J$6:$J$30<>"Not started"))=0,"",IF(SUMPRODUCT(('Regular Clients'!$C$6:$C$30=H$5)*('Regular Clients'!$B$6:$B$30=$B$3)*('Regular Clients'!$D$6:$D$30<=$A9)*('Regular Clients'!$E$6:$E$30>$A9)*('Regular Clients'!$J$6:$J$30<>"Ended")*('Regular Clients'!$J$6:$J$30<>"Not started"))>1,"CLASH",INDEX('Regular Clients'!$A$6:$A$30,SUMPRODUCT(MAX(('Regular Clients'!$C$6:$C$30=H$5)*('Regular Clients'!$B$6:$B$30=$B$3)*('Regular Clients'!$D$6:$D$30<=$A9)*('Regular Clients'!$E$6:$E$30>$A9)*('Regular Clients'!$J$6:$J$30<>"Ended")*('Regular Clients'!$J$6:$J$30<>"Not started")*(ROW('Regular Clients'!$A$6:$A$30)-ROW('Regular Clients'!$A$6)+1))))))
A10: 0.45833333 | B10: =IF(SUMPRODUCT(('Regular Clients'!$C$6:$C$30=B$5)*('Regular Clients'!$B$6:$B$30=$B$3)*('Regular Clients'!$D$6:$D$30<=$A10)*('Regular Clients'!$E$6:$E$30>$A10)*('Regular Clients'!$J$6:$J$30<>"Ended")*('Regular Clients'!$J$6:$J$30<>"Not started"))=0,"",IF(SUMPRODUCT(('Regular Clients'!$C$6:$C$30=B$5)*('Regular Clients'!$B$6:$B$30=$B$3)*('Regular Clients'!$D$6:$D$30<=$A10)*('Regular Clients'!$E$6:$E$30>$A10)*('Regular Clients'!$J$6:$J$30<>"Ended")*('Regular Clients'!$J$6:$J$30<>"Not started"))>1,"CLASH",INDEX('Regular Clients'!$A$6:$A$30,SUMPRODUCT(MAX(('Regular Clients'!$C$6:$C$30=B$5)*('Regular Clients'!$B$6:$B$30=$B$3)*('Regular Clients'!$D$6:$D$30<=$A10)*('Regular Clients'!$E$6:$E$30>$A10)*('Regular Clients'!$J$6:$J$30<>"Ended")*('Regular Clients'!$J$6:$J$30<>"Not started")*(ROW('Regular Clients'!$A$6:$A$30)-ROW('Regular Clients'!$A$6)+1)))))) | C10: =IF(SUMPRODUCT(('Regular Clients'!$C$6:$C$30=C$5)*('Regular Clients'!$B$6:$B$30=$B$3)*('Regular Clients'!$D$6:$D$30<=$A10)*('Regular Clients'!$E$6:$E$30>$A10)*('Regular Clients'!$J$6:$J$30<>"Ended")*('Regular Clients'!$J$6:$J$30<>"Not started"))=0,"",IF(SUMPRODUCT(('Regular Clients'!$C$6:$C$30=C$5)*('Regular Clients'!$B$6:$B$30=$B$3)*('Regular Clients'!$D$6:$D$30<=$A10)*('Regular Clients'!$E$6:$E$30>$A10)*('Regular Clients'!$J$6:$J$30<>"Ended")*('Regular Clients'!$J$6:$J$30<>"Not started"))>1,"CLASH",INDEX('Regular Clients'!$A$6:$A$30,SUMPRODUCT(MAX(('Regular Clients'!$C$6:$C$30=C$5)*('Regular Clients'!$B$6:$B$30=$B$3)*('Regular Clients'!$D$6:$D$30<=$A10)*('Regular Clients'!$E$6:$E$30>$A10)*('Regular Clients'!$J$6:$J$30<>"Ended")*('Regular Clients'!$J$6:$J$30<>"Not started")*(ROW('Regular Clients'!$A$6:$A$30)-ROW('Regular Clients'!$A$6)+1)))))) | D10: =IF(SUMPRODUCT(('Regular Clients'!$C$6:$C$30=D$5)*('Regular Clients'!$B$6:$B$30=$B$3)*('Regular Clients'!$D$6:$D$30<=$A10)*('Regular Clients'!$E$6:$E$30>$A10)*('Regular Clients'!$J$6:$J$30<>"Ended")*('Regular Clients'!$J$6:$J$30<>"Not started"))=0,"",IF(SUMPRODUCT(('Regular Clients'!$C$6:$C$30=D$5)*('Regular Clients'!$B$6:$B$30=$B$3)*('Regular Clients'!$D$6:$D$30<=$A10)*('Regular Clients'!$E$6:$E$30>$A10)*('Regular Clients'!$J$6:$J$30<>"Ended")*('Regular Clients'!$J$6:$J$30<>"Not started"))>1,"CLASH",INDEX('Regular Clients'!$A$6:$A$30,SUMPRODUCT(MAX(('Regular Clients'!$C$6:$C$30=D$5)*('Regular Clients'!$B$6:$B$30=$B$3)*('Regular Clients'!$D$6:$D$30<=$A10)*('Regular Clients'!$E$6:$E$30>$A10)*('Regular Clients'!$J$6:$J$30<>"Ended")*('Regular Clients'!$J$6:$J$30<>"Not started")*(ROW('Regular Clients'!$A$6:$A$30)-ROW('Regular Clients'!$A$6)+1)))))) | E10: =IF(SUMPRODUCT(('Regular Clients'!$C$6:$C$30=E$5)*('Regular Clients'!$B$6:$B$30=$B$3)*('Regular Clients'!$D$6:$D$30<=$A10)*('Regular Clients'!$E$6:$E$30>$A10)*('Regular Clients'!$J$6:$J$30<>"Ended")*('Regular Clients'!$J$6:$J$30<>"Not started"))=0,"",IF(SUMPRODUCT(('Regular Clients'!$C$6:$C$30=E$5)*('Regular Clients'!$B$6:$B$30=$B$3)*('Regular Clients'!$D$6:$D$30<=$A10)*('Regular Clients'!$E$6:$E$30>$A10)*('Regular Clients'!$J$6:$J$30<>"Ended")*('Regular Clients'!$J$6:$J$30<>"Not started"))>1,"CLASH",INDEX('Regular Clients'!$A$6:$A$30,SUMPRODUCT(MAX(('Regular Clients'!$C$6:$C$30=E$5)*('Regular Clients'!$B$6:$B$30=$B$3)*('Regular Clients'!$D$6:$D$30<=$A10)*('Regular Clients'!$E$6:$E$30>$A10)*('Regular Clients'!$J$6:$J$30<>"Ended")*('Regular Clients'!$J$6:$J$30<>"Not started")*(ROW('Regular Clients'!$A$6:$A$30)-ROW('Regular Clients'!$A$6)+1)))))) | F10: =IF(SUMPRODUCT(('Regular Clients'!$C$6:$C$30=F$5)*('Regular Clients'!$B$6:$B$30=$B$3)*('Regular Clients'!$D$6:$D$30<=$A10)*('Regular Clients'!$E$6:$E$30>$A10)*('Regular Clients'!$J$6:$J$30<>"Ended")*('Regular Clients'!$J$6:$J$30<>"Not started"))=0,"",IF(SUMPRODUCT(('Regular Clients'!$C$6:$C$30=F$5)*('Regular Clients'!$B$6:$B$30=$B$3)*('Regular Clients'!$D$6:$D$30<=$A10)*('Regular Clients'!$E$6:$E$30>$A10)*('Regular Clients'!$J$6:$J$30<>"Ended")*('Regular Clients'!$J$6:$J$30<>"Not started"))>1,"CLASH",INDEX('Regular Clients'!$A$6:$A$30,SUMPRODUCT(MAX(('Regular Clients'!$C$6:$C$30=F$5)*('Regular Clients'!$B$6:$B$30=$B$3)*('Regular Clients'!$D$6:$D$30<=$A10)*('Regular Clients'!$E$6:$E$30>$A10)*('Regular Clients'!$J$6:$J$30<>"Ended")*('Regular Clients'!$J$6:$J$30<>"Not started")*(ROW('Regular Clients'!$A$6:$A$30)-ROW('Regular Clients'!$A$6)+1)))))) | G10: =IF(SUMPRODUCT(('Regular Clients'!$C$6:$C$30=G$5)*('Regular Clients'!$B$6:$B$30=$B$3)*('Regular Clients'!$D$6:$D$30<=$A10)*('Regular Clients'!$E$6:$E$30>$A10)*('Regular Clients'!$J$6:$J$30<>"Ended")*('Regular Clients'!$J$6:$J$30<>"Not started"))=0,"",IF(SUMPRODUCT(('Regular Clients'!$C$6:$C$30=G$5)*('Regular Clients'!$B$6:$B$30=$B$3)*('Regular Clients'!$D$6:$D$30<=$A10)*('Regular Clients'!$E$6:$E$30>$A10)*('Regular Clients'!$J$6:$J$30<>"Ended")*('Regular Clients'!$J$6:$J$30<>"Not started"))>1,"CLASH",INDEX('Regular Clients'!$A$6:$A$30,SUMPRODUCT(MAX(('Regular Clients'!$C$6:$C$30=G$5)*('Regular Clients'!$B$6:$B$30=$B$3)*('Regular Clients'!$D$6:$D$30<=$A10)*('Regular Clients'!$E$6:$E$30>$A10)*('Regular Clients'!$J$6:$J$30<>"Ended")*('Regular Clients'!$J$6:$J$30<>"Not started")*(ROW('Regular Clients'!$A$6:$A$30)-ROW('Regular Clients'!$A$6)+1)))))) | H10: =IF(SUMPRODUCT(('Regular Clients'!$C$6:$C$30=H$5)*('Regular Clients'!$B$6:$B$30=$B$3)*('Regular Clients'!$D$6:$D$30<=$A10)*('Regular Clients'!$E$6:$E$30>$A10)*('Regular Clients'!$J$6:$J$30<>"Ended")*('Regular Clients'!$J$6:$J$30<>"Not started"))=0,"",IF(SUMPRODUCT(('Regular Clients'!$C$6:$C$30=H$5)*('Regular Clients'!$B$6:$B$30=$B$3)*('Regular Clients'!$D$6:$D$30<=$A10)*('Regular Clients'!$E$6:$E$30>$A10)*('Regular Clients'!$J$6:$J$30<>"Ended")*('Regular Clients'!$J$6:$J$30<>"Not started"))>1,"CLASH",INDEX('Regular Clients'!$A$6:$A$30,SUMPRODUCT(MAX(('Regular Clients'!$C$6:$C$30=H$5)*('Regular Clients'!$B$6:$B$30=$B$3)*('Regular Clients'!$D$6:$D$30<=$A10)*('Regular Clients'!$E$6:$E$30>$A10)*('Regular Clients'!$J$6:$J$30<>"Ended")*('Regular Clients'!$J$6:$J$30<>"Not started")*(ROW('Regular Clients'!$A$6:$A$30)-ROW('Regular Clients'!$A$6)+1))))))
A11: 0.5 | B11: =IF(SUMPRODUCT(('Regular Clients'!$C$6:$C$30=B$5)*('Regular Clients'!$B$6:$B$30=$B$3)*('Regular Clients'!$D$6:$D$30<=$A11)*('Regular Clients'!$E$6:$E$30>$A11)*('Regular Clients'!$J$6:$J$30<>"Ended")*('Regular Clients'!$J$6:$J$30<>"Not started"))=0,"",IF(SUMPRODUCT(('Regular Clients'!$C$6:$C$30=B$5)*('Regular Clients'!$B$6:$B$30=$B$3)*('Regular Clients'!$D$6:$D$30<=$A11)*('Regular Clients'!$E$6:$E$30>$A11)*('Regular Clients'!$J$6:$J$30<>"Ended")*('Regular Clients'!$J$6:$J$30<>"Not started"))>1,"CLASH",INDEX('Regular Clients'!$A$6:$A$30,SUMPRODUCT(MAX(('Regular Clients'!$C$6:$C$30=B$5)*('Regular Clients'!$B$6:$B$30=$B$3)*('Regular Clients'!$D$6:$D$30<=$A11)*('Regular Clients'!$E$6:$E$30>$A11)*('Regular Clients'!$J$6:$J$30<>"Ended")*('Regular Clients'!$J$6:$J$30<>"Not started")*(ROW('Regular Clients'!$A$6:$A$30)-ROW('Regular Clients'!$A$6)+1)))))) | C11: =IF(SUMPRODUCT(('Regular Clients'!$C$6:$C$30=C$5)*('Regular Clients'!$B$6:$B$30=$B$3)*('Regular Clients'!$D$6:$D$30<=$A11)*('Regular Clients'!$E$6:$E$30>$A11)*('Regular Clients'!$J$6:$J$30<>"Ended")*('Regular Clients'!$J$6:$J$30<>"Not started"))=0,"",IF(SUMPRODUCT(('Regular Clients'!$C$6:$C$30=C$5)*('Regular Clients'!$B$6:$B$30=$B$3)*('Regular Clients'!$D$6:$D$30<=$A11)*('Regular Clients'!$E$6:$E$30>$A11)*('Regular Clients'!$J$6:$J$30<>"Ended")*('Regular Clients'!$J$6:$J$30<>"Not started"))>1,"CLASH",INDEX('Regular Clients'!$A$6:$A$30,SUMPRODUCT(MAX(('Regular Clients'!$C$6:$C$30=C$5)*('Regular Clients'!$B$6:$B$30=$B$3)*('Regular Clients'!$D$6:$D$30<=$A11)*('Regular Clients'!$E$6:$E$30>$A11)*('Regular Clients'!$J$6:$J$30<>"Ended")*('Regular Clients'!$J$6:$J$30<>"Not started")*(ROW('Regular Clients'!$A$6:$A$30)-ROW('Regular Clients'!$A$6)+1)))))) | D11: =IF(SUMPRODUCT(('Regular Clients'!$C$6:$C$30=D$5)*('Regular Clients'!$B$6:$B$30=$B$3)*('Regular Clients'!$D$6:$D$30<=$A11)*('Regular Clients'!$E$6:$E$30>$A11)*('Regular Clients'!$J$6:$J$30<>"Ended")*('Regular Clients'!$J$6:$J$30<>"Not started"))=0,"",IF(SUMPRODUCT(('Regular Clients'!$C$6:$C$30=D$5)*('Regular Clients'!$B$6:$B$30=$B$3)*('Regular Clients'!$D$6:$D$30<=$A11)*('Regular Clients'!$E$6:$E$30>$A11)*('Regular Clients'!$J$6:$J$30<>"Ended")*('Regular Clients'!$J$6:$J$30<>"Not started"))>1,"CLASH",INDEX('Regular Clients'!$A$6:$A$30,SUMPRODUCT(MAX(('Regular Clients'!$C$6:$C$30=D$5)*('Regular Clients'!$B$6:$B$30=$B$3)*('Regular Clients'!$D$6:$D$30<=$A11)*('Regular Clients'!$E$6:$E$30>$A11)*('Regular Clients'!$J$6:$J$30<>"Ended")*('Regular Clients'!$J$6:$J$30<>"Not started")*(ROW('Regular Clients'!$A$6:$A$30)-ROW('Regular Clients'!$A$6)+1)))))) | E11: =IF(SUMPRODUCT(('Regular Clients'!$C$6:$C$30=E$5)*('Regular Clients'!$B$6:$B$30=$B$3)*('Regular Clients'!$D$6:$D$30<=$A11)*('Regular Clients'!$E$6:$E$30>$A11)*('Regular Clients'!$J$6:$J$30<>"Ended")*('Regular Clients'!$J$6:$J$30<>"Not started"))=0,"",IF(SUMPRODUCT(('Regular Clients'!$C$6:$C$30=E$5)*('Regular Clients'!$B$6:$B$30=$B$3)*('Regular Clients'!$D$6:$D$30<=$A11)*('Regular Clients'!$E$6:$E$30>$A11)*('Regular Clients'!$J$6:$J$30<>"Ended")*('Regular Clients'!$J$6:$J$30<>"Not started"))>1,"CLASH",INDEX('Regular Clients'!$A$6:$A$30,SUMPRODUCT(MAX(('Regular Clients'!$C$6:$C$30=E$5)*('Regular Clients'!$B$6:$B$30=$B$3)*('Regular Clients'!$D$6:$D$30<=$A11)*('Regular Clients'!$E$6:$E$30>$A11)*('Regular Clients'!$J$6:$J$30<>"Ended")*('Regular Clients'!$J$6:$J$30<>"Not started")*(ROW('Regular Clients'!$A$6:$A$30)-ROW('Regular Clients'!$A$6)+1)))))) | F11: =IF(SUMPRODUCT(('Regular Clients'!$C$6:$C$30=F$5)*('Regular Clients'!$B$6:$B$30=$B$3)*('Regular Clients'!$D$6:$D$30<=$A11)*('Regular Clients'!$E$6:$E$30>$A11)*('Regular Clients'!$J$6:$J$30<>"Ended")*('Regular Clients'!$J$6:$J$30<>"Not started"))=0,"",IF(SUMPRODUCT(('Regular Clients'!$C$6:$C$30=F$5)*('Regular Clients'!$B$6:$B$30=$B$3)*('Regular Clients'!$D$6:$D$30<=$A11)*('Regular Clients'!$E$6:$E$30>$A11)*('Regular Clients'!$J$6:$J$30<>"Ended")*('Regular Clients'!$J$6:$J$30<>"Not started"))>1,"CLASH",INDEX('Regular Clients'!$A$6:$A$30,SUMPRODUCT(MAX(('Regular Clients'!$C$6:$C$30=F$5)*('Regular Clients'!$B$6:$B$30=$B$3)*('Regular Clients'!$D$6:$D$30<=$A11)*('Regular Clients'!$E$6:$E$30>$A11)*('Regular Clients'!$J$6:$J$30<>"Ended")*('Regular Clients'!$J$6:$J$30<>"Not started")*(ROW('Regular Clients'!$A$6:$A$30)-ROW('Regular Clients'!$A$6)+1)))))) | G11: =IF(SUMPRODUCT(('Regular Clients'!$C$6:$C$30=G$5)*('Regular Clients'!$B$6:$B$30=$B$3)*('Regular Clients'!$D$6:$D$30<=$A11)*('Regular Clients'!$E$6:$E$30>$A11)*('Regular Clients'!$J$6:$J$30<>"Ended")*('Regular Clients'!$J$6:$J$30<>"Not started"))=0,"",IF(SUMPRODUCT(('Regular Clients'!$C$6:$C$30=G$5)*('Regular Clients'!$B$6:$B$30=$B$3)*('Regular Clients'!$D$6:$D$30<=$A11)*('Regular Clients'!$E$6:$E$30>$A11)*('Regular Clients'!$J$6:$J$30<>"Ended")*('Regular Clients'!$J$6:$J$30<>"Not started"))>1,"CLASH",INDEX('Regular Clients'!$A$6:$A$30,SUMPRODUCT(MAX(('Regular Clients'!$C$6:$C$30=G$5)*('Regular Clients'!$B$6:$B$30=$B$3)*('Regular Clients'!$D$6:$D$30<=$A11)*('Regular Clients'!$E$6:$E$30>$A11)*('Regular Clients'!$J$6:$J$30<>"Ended")*('Regular Clients'!$J$6:$J$30<>"Not started")*(ROW('Regular Clients'!$A$6:$A$30)-ROW('Regular Clients'!$A$6)+1)))))) | H11: =IF(SUMPRODUCT(('Regular Clients'!$C$6:$C$30=H$5)*('Regular Clients'!$B$6:$B$30=$B$3)*('Regular Clients'!$D$6:$D$30<=$A11)*('Regular Clients'!$E$6:$E$30>$A11)*('Regular Clients'!$J$6:$J$30<>"Ended")*('Regular Clients'!$J$6:$J$30<>"Not started"))=0,"",IF(SUMPRODUCT(('Regular Clients'!$C$6:$C$30=H$5)*('Regular Clients'!$B$6:$B$30=$B$3)*('Regular Clients'!$D$6:$D$30<=$A11)*('Regular Clients'!$E$6:$E$30>$A11)*('Regular Clients'!$J$6:$J$30<>"Ended")*('Regular Clients'!$J$6:$J$30<>"Not started"))>1,"CLASH",INDEX('Regular Clients'!$A$6:$A$30,SUMPRODUCT(MAX(('Regular Clients'!$C$6:$C$30=H$5)*('Regular Clients'!$B$6:$B$30=$B$3)*('Regular Clients'!$D$6:$D$30<=$A11)*('Regular Clients'!$E$6:$E$30>$A11)*('Regular Clients'!$J$6:$J$30<>"Ended")*('Regular Clients'!$J$6:$J$30<>"Not started")*(ROW('Regular Clients'!$A$6:$A$30)-ROW('Regular Clients'!$A$6)+1))))))
A12: 0.54166667 | B12: =IF(SUMPRODUCT(('Regular Clients'!$C$6:$C$30=B$5)*('Regular Clients'!$B$6:$B$30=$B$3)*('Regular Clients'!$D$6:$D$30<=$A12)*('Regular Clients'!$E$6:$E$30>$A12)*('Regular Clients'!$J$6:$J$30<>"Ended")*('Regular Clients'!$J$6:$J$30<>"Not started"))=0,"",IF(SUMPRODUCT(('Regular Clients'!$C$6:$C$30=B$5)*('Regular Clients'!$B$6:$B$30=$B$3)*('Regular Clients'!$D$6:$D$30<=$A12)*('Regular Clients'!$E$6:$E$30>$A12)*('Regular Clients'!$J$6:$J$30<>"Ended")*('Regular Clients'!$J$6:$J$30<>"Not started"))>1,"CLASH",INDEX('Regular Clients'!$A$6:$A$30,SUMPRODUCT(MAX(('Regular Clients'!$C$6:$C$30=B$5)*('Regular Clients'!$B$6:$B$30=$B$3)*('Regular Clients'!$D$6:$D$30<=$A12)*('Regular Clients'!$E$6:$E$30>$A12)*('Regular Clients'!$J$6:$J$30<>"Ended")*('Regular Clients'!$J$6:$J$30<>"Not started")*(ROW('Regular Clients'!$A$6:$A$30)-ROW('Regular Clients'!$A$6)+1)))))) | C12: =IF(SUMPRODUCT(('Regular Clients'!$C$6:$C$30=C$5)*('Regular Clients'!$B$6:$B$30=$B$3)*('Regular Clients'!$D$6:$D$30<=$A12)*('Regular Clients'!$E$6:$E$30>$A12)*('Regular Clients'!$J$6:$J$30<>"Ended")*('Regular Clients'!$J$6:$J$30<>"Not started"))=0,"",IF(SUMPRODUCT(('Regular Clients'!$C$6:$C$30=C$5)*('Regular Clients'!$B$6:$B$30=$B$3)*('Regular Clients'!$D$6:$D$30<=$A12)*('Regular Clients'!$E$6:$E$30>$A12)*('Regular Clients'!$J$6:$J$30<>"Ended")*('Regular Clients'!$J$6:$J$30<>"Not started"))>1,"CLASH",INDEX('Regular Clients'!$A$6:$A$30,SUMPRODUCT(MAX(('Regular Clients'!$C$6:$C$30=C$5)*('Regular Clients'!$B$6:$B$30=$B$3)*('Regular Clients'!$D$6:$D$30<=$A12)*('Regular Clients'!$E$6:$E$30>$A12)*('Regular Clients'!$J$6:$J$30<>"Ended")*('Regular Clients'!$J$6:$J$30<>"Not started")*(ROW('Regular Clients'!$A$6:$A$30)-ROW('Regular Clients'!$A$6)+1)))))) | D12: =IF(SUMPRODUCT(('Regular Clients'!$C$6:$C$30=D$5)*('Regular Clients'!$B$6:$B$30=$B$3)*('Regular Clients'!$D$6:$D$30<=$A12)*('Regular Clients'!$E$6:$E$30>$A12)*('Regular Clients'!$J$6:$J$30<>"Ended")*('Regular Clients'!$J$6:$J$30<>"Not started"))=0,"",IF(SUMPRODUCT(('Regular Clients'!$C$6:$C$30=D$5)*('Regular Clients'!$B$6:$B$30=$B$3)*('Regular Clients'!$D$6:$D$30<=$A12)*('Regular Clients'!$E$6:$E$30>$A12)*('Regular Clients'!$J$6:$J$30<>"Ended")*('Regular Clients'!$J$6:$J$30<>"Not started"))>1,"CLASH",INDEX('Regular Clients'!$A$6:$A$30,SUMPRODUCT(MAX(('Regular Clients'!$C$6:$C$30=D$5)*('Regular Clients'!$B$6:$B$30=$B$3)*('Regular Clients'!$D$6:$D$30<=$A12)*('Regular Clients'!$E$6:$E$30>$A12)*('Regular Clients'!$J$6:$J$30<>"Ended")*('Regular Clients'!$J$6:$J$30<>"Not started")*(ROW('Regular Clients'!$A$6:$A$30)-ROW('Regular Clients'!$A$6)+1)))))) | E12: =IF(SUMPRODUCT(('Regular Clients'!$C$6:$C$30=E$5)*('Regular Clients'!$B$6:$B$30=$B$3)*('Regular Clients'!$D$6:$D$30<=$A12)*('Regular Clients'!$E$6:$E$30>$A12)*('Regular Clients'!$J$6:$J$30<>"Ended")*('Regular Clients'!$J$6:$J$30<>"Not started"))=0,"",IF(SUMPRODUCT(('Regular Clients'!$C$6:$C$30=E$5)*('Regular Clients'!$B$6:$B$30=$B$3)*('Regular Clients'!$D$6:$D$30<=$A12)*('Regular Clients'!$E$6:$E$30>$A12)*('Regular Clients'!$J$6:$J$30<>"Ended")*('Regular Clients'!$J$6:$J$30<>"Not started"))>1,"CLASH",INDEX('Regular Clients'!$A$6:$A$30,SUMPRODUCT(MAX(('Regular Clients'!$C$6:$C$30=E$5)*('Regular Clients'!$B$6:$B$30=$B$3)*('Regular Clients'!$D$6:$D$30<=$A12)*('Regular Clients'!$E$6:$E$30>$A12)*('Regular Clients'!$J$6:$J$30<>"Ended")*('Regular Clients'!$J$6:$J$30<>"Not started")*(ROW('Regular Clients'!$A$6:$A$30)-ROW('Regular Clients'!$A$6)+1)))))) | F12: =IF(SUMPRODUCT(('Regular Clients'!$C$6:$C$30=F$5)*('Regular Clients'!$B$6:$B$30=$B$3)*('Regular Clients'!$D$6:$D$30<=$A12)*('Regular Clients'!$E$6:$E$30>$A12)*('Regular Clients'!$J$6:$J$30<>"Ended")*('Regular Clients'!$J$6:$J$30<>"Not started"))=0,"",IF(SUMPRODUCT(('Regular Clients'!$C$6:$C$30=F$5)*('Regular Clients'!$B$6:$B$30=$B$3)*('Regular Clients'!$D$6:$D$30<=$A12)*('Regular Clients'!$E$6:$E$30>$A12)*('Regular Clients'!$J$6:$J$30<>"Ended")*('Regular Clients'!$J$6:$J$30<>"Not started"))>1,"CLASH",INDEX('Regular Clients'!$A$6:$A$30,SUMPRODUCT(MAX(('Regular Clients'!$C$6:$C$30=F$5)*('Regular Clients'!$B$6:$B$30=$B$3)*('Regular Clients'!$D$6:$D$30<=$A12)*('Regular Clients'!$E$6:$E$30>$A12)*('Regular Clients'!$J$6:$J$30<>"Ended")*('Regular Clients'!$J$6:$J$30<>"Not started")*(ROW('Regular Clients'!$A$6:$A$30)-ROW('Regular Clients'!$A$6)+1)))))) | G12: =IF(SUMPRODUCT(('Regular Clients'!$C$6:$C$30=G$5)*('Regular Clients'!$B$6:$B$30=$B$3)*('Regular Clients'!$D$6:$D$30<=$A12)*('Regular Clients'!$E$6:$E$30>$A12)*('Regular Clients'!$J$6:$J$30<>"Ended")*('Regular Clients'!$J$6:$J$30<>"Not started"))=0,"",IF(SUMPRODUCT(('Regular Clients'!$C$6:$C$30=G$5)*('Regular Clients'!$B$6:$B$30=$B$3)*('Regular Clients'!$D$6:$D$30<=$A12)*('Regular Clients'!$E$6:$E$30>$A12)*('Regular Clients'!$J$6:$J$30<>"Ended")*('Regular Clients'!$J$6:$J$30<>"Not started"))>1,"CLASH",INDEX('Regular Clients'!$A$6:$A$30,SUMPRODUCT(MAX(('Regular Clients'!$C$6:$C$30=G$5)*('Regular Clients'!$B$6:$B$30=$B$3)*('Regular Clients'!$D$6:$D$30<=$A12)*('Regular Clients'!$E$6:$E$30>$A12)*('Regular Clients'!$J$6:$J$30<>"Ended")*('Regular Clients'!$J$6:$J$30<>"Not started")*(ROW('Regular Clients'!$A$6:$A$30)-ROW('Regular Clients'!$A$6)+1)))))) | H12: =IF(SUMPRODUCT(('Regular Clients'!$C$6:$C$30=H$5)*('Regular Clients'!$B$6:$B$30=$B$3)*('Regular Clients'!$D$6:$D$30<=$A12)*('Regular Clients'!$E$6:$E$30>$A12)*('Regular Clients'!$J$6:$J$30<>"Ended")*('Regular Clients'!$J$6:$J$30<>"Not started"))=0,"",IF(SUMPRODUCT(('Regular Clients'!$C$6:$C$30=H$5)*('Regular Clients'!$B$6:$B$30=$B$3)*('Regular Clients'!$D$6:$D$30<=$A12)*('Regular Clients'!$E$6:$E$30>$A12)*('Regular Clients'!$J$6:$J$30<>"Ended")*('Regular Clients'!$J$6:$J$30<>"Not started"))>1,"CLASH",INDEX('Regular Clients'!$A$6:$A$30,SUMPRODUCT(MAX(('Regular Clients'!$C$6:$C$30=H$5)*('Regular Clients'!$B$6:$B$30=$B$3)*('Regular Clients'!$D$6:$D$30<=$A12)*('Regular Clients'!$E$6:$E$30>$A12)*('Regular Clients'!$J$6:$J$30<>"Ended")*('Regular Clients'!$J$6:$J$30<>"Not started")*(ROW('Regular Clients'!$A$6:$A$30)-ROW('Regular Clients'!$A$6)+1))))))
A13: 0.58333333 | B13: =IF(SUMPRODUCT(('Regular Clients'!$C$6:$C$30=B$5)*('Regular Clients'!$B$6:$B$30=$B$3)*('Regular Clients'!$D$6:$D$30<=$A13)*('Regular Clients'!$E$6:$E$30>$A13)*('Regular Clients'!$J$6:$J$30<>"Ended")*('Regular Clients'!$J$6:$J$30<>"Not started"))=0,"",IF(SUMPRODUCT(('Regular Clients'!$C$6:$C$30=B$5)*('Regular Clients'!$B$6:$B$30=$B$3)*('Regular Clients'!$D$6:$D$30<=$A13)*('Regular Clients'!$E$6:$E$30>$A13)*('Regular Clients'!$J$6:$J$30<>"Ended")*('Regular Clients'!$J$6:$J$30<>"Not started"))>1,"CLASH",INDEX('Regular Clients'!$A$6:$A$30,SUMPRODUCT(MAX(('Regular Clients'!$C$6:$C$30=B$5)*('Regular Clients'!$B$6:$B$30=$B$3)*('Regular Clients'!$D$6:$D$30<=$A13)*('Regular Clients'!$E$6:$E$30>$A13)*('Regular Clients'!$J$6:$J$30<>"Ended")*('Regular Clients'!$J$6:$J$30<>"Not started")*(ROW('Regular Clients'!$A$6:$A$30)-ROW('Regular Clients'!$A$6)+1)))))) | C13: =IF(SUMPRODUCT(('Regular Clients'!$C$6:$C$30=C$5)*('Regular Clients'!$B$6:$B$30=$B$3)*('Regular Clients'!$D$6:$D$30<=$A13)*('Regular Clients'!$E$6:$E$30>$A13)*('Regular Clients'!$J$6:$J$30<>"Ended")*('Regular Clients'!$J$6:$J$30<>"Not started"))=0,"",IF(SUMPRODUCT(('Regular Clients'!$C$6:$C$30=C$5)*('Regular Clients'!$B$6:$B$30=$B$3)*('Regular Clients'!$D$6:$D$30<=$A13)*('Regular Clients'!$E$6:$E$30>$A13)*('Regular Clients'!$J$6:$J$30<>"Ended")*('Regular Clients'!$J$6:$J$30<>"Not started"))>1,"CLASH",INDEX('Regular Clients'!$A$6:$A$30,SUMPRODUCT(MAX(('Regular Clients'!$C$6:$C$30=C$5)*('Regular Clients'!$B$6:$B$30=$B$3)*('Regular Clients'!$D$6:$D$30<=$A13)*('Regular Clients'!$E$6:$E$30>$A13)*('Regular Clients'!$J$6:$J$30<>"Ended")*('Regular Clients'!$J$6:$J$30<>"Not started")*(ROW('Regular Clients'!$A$6:$A$30)-ROW('Regular Clients'!$A$6)+1)))))) | D13: =IF(SUMPRODUCT(('Regular Clients'!$C$6:$C$30=D$5)*('Regular Clients'!$B$6:$B$30=$B$3)*('Regular Clients'!$D$6:$D$30<=$A13)*('Regular Clients'!$E$6:$E$30>$A13)*('Regular Clients'!$J$6:$J$30<>"Ended")*('Regular Clients'!$J$6:$J$30<>"Not started"))=0,"",IF(SUMPRODUCT(('Regular Clients'!$C$6:$C$30=D$5)*('Regular Clients'!$B$6:$B$30=$B$3)*('Regular Clients'!$D$6:$D$30<=$A13)*('Regular Clients'!$E$6:$E$30>$A13)*('Regular Clients'!$J$6:$J$30<>"Ended")*('Regular Clients'!$J$6:$J$30<>"Not started"))>1,"CLASH",INDEX('Regular Clients'!$A$6:$A$30,SUMPRODUCT(MAX(('Regular Clients'!$C$6:$C$30=D$5)*('Regular Clients'!$B$6:$B$30=$B$3)*('Regular Clients'!$D$6:$D$30<=$A13)*('Regular Clients'!$E$6:$E$30>$A13)*('Regular Clients'!$J$6:$J$30<>"Ended")*('Regular Clients'!$J$6:$J$30<>"Not started")*(ROW('Regular Clients'!$A$6:$A$30)-ROW('Regular Clients'!$A$6)+1)))))) | E13: =IF(SUMPRODUCT(('Regular Clients'!$C$6:$C$30=E$5)*('Regular Clients'!$B$6:$B$30=$B$3)*('Regular Clients'!$D$6:$D$30<=$A13)*('Regular Clients'!$E$6:$E$30>$A13)*('Regular Clients'!$J$6:$J$30<>"Ended")*('Regular Clients'!$J$6:$J$30<>"Not started"))=0,"",IF(SUMPRODUCT(('Regular Clients'!$C$6:$C$30=E$5)*('Regular Clients'!$B$6:$B$30=$B$3)*('Regular Clients'!$D$6:$D$30<=$A13)*('Regular Clients'!$E$6:$E$30>$A13)*('Regular Clients'!$J$6:$J$30<>"Ended")*('Regular Clients'!$J$6:$J$30<>"Not started"))>1,"CLASH",INDEX('Regular Clients'!$A$6:$A$30,SUMPRODUCT(MAX(('Regular Clients'!$C$6:$C$30=E$5)*('Regular Clients'!$B$6:$B$30=$B$3)*('Regular Clients'!$D$6:$D$30<=$A13)*('Regular Clients'!$E$6:$E$30>$A13)*('Regular Clients'!$J$6:$J$30<>"Ended")*('Regular Clients'!$J$6:$J$30<>"Not started")*(ROW('Regular Clients'!$A$6:$A$30)-ROW('Regular Clients'!$A$6)+1)))))) | F13: =IF(SUMPRODUCT(('Regular Clients'!$C$6:$C$30=F$5)*('Regular Clients'!$B$6:$B$30=$B$3)*('Regular Clients'!$D$6:$D$30<=$A13)*('Regular Clients'!$E$6:$E$30>$A13)*('Regular Clients'!$J$6:$J$30<>"Ended")*('Regular Clients'!$J$6:$J$30<>"Not started"))=0,"",IF(SUMPRODUCT(('Regular Clients'!$C$6:$C$30=F$5)*('Regular Clients'!$B$6:$B$30=$B$3)*('Regular Clients'!$D$6:$D$30<=$A13)*('Regular Clients'!$E$6:$E$30>$A13)*('Regular Clients'!$J$6:$J$30<>"Ended")*('Regular Clients'!$J$6:$J$30<>"Not started"))>1,"CLASH",INDEX('Regular Clients'!$A$6:$A$30,SUMPRODUCT(MAX(('Regular Clients'!$C$6:$C$30=F$5)*('Regular Clients'!$B$6:$B$30=$B$3)*('Regular Clients'!$D$6:$D$30<=$A13)*('Regular Clients'!$E$6:$E$30>$A13)*('Regular Clients'!$J$6:$J$30<>"Ended")*('Regular Clients'!$J$6:$J$30<>"Not started")*(ROW('Regular Clients'!$A$6:$A$30)-ROW('Regular Clients'!$A$6)+1)))))) | G13: =IF(SUMPRODUCT(('Regular Clients'!$C$6:$C$30=G$5)*('Regular Clients'!$B$6:$B$30=$B$3)*('Regular Clients'!$D$6:$D$30<=$A13)*('Regular Clients'!$E$6:$E$30>$A13)*('Regular Clients'!$J$6:$J$30<>"Ended")*('Regular Clients'!$J$6:$J$30<>"Not started"))=0,"",IF(SUMPRODUCT(('Regular Clients'!$C$6:$C$30=G$5)*('Regular Clients'!$B$6:$B$30=$B$3)*('Regular Clients'!$D$6:$D$30<=$A13)*('Regular Clients'!$E$6:$E$30>$A13)*('Regular Clients'!$J$6:$J$30<>"Ended")*('Regular Clients'!$J$6:$J$30<>"Not started"))>1,"CLASH",INDEX('Regular Clients'!$A$6:$A$30,SUMPRODUCT(MAX(('Regular Clients'!$C$6:$C$30=G$5)*('Regular Clients'!$B$6:$B$30=$B$3)*('Regular Clients'!$D$6:$D$30<=$A13)*('Regular Clients'!$E$6:$E$30>$A13)*('Regular Clients'!$J$6:$J$30<>"Ended")*('Regular Clients'!$J$6:$J$30<>"Not started")*(ROW('Regular Clients'!$A$6:$A$30)-ROW('Regular Clients'!$A$6)+1)))))) | H13: =IF(SUMPRODUCT(('Regular Clients'!$C$6:$C$30=H$5)*('Regular Clients'!$B$6:$B$30=$B$3)*('Regular Clients'!$D$6:$D$30<=$A13)*('Regular Clients'!$E$6:$E$30>$A13)*('Regular Clients'!$J$6:$J$30<>"Ended")*('Regular Clients'!$J$6:$J$30<>"Not started"))=0,"",IF(SUMPRODUCT(('Regular Clients'!$C$6:$C$30=H$5)*('Regular Clients'!$B$6:$B$30=$B$3)*('Regular Clients'!$D$6:$D$30<=$A13)*('Regular Clients'!$E$6:$E$30>$A13)*('Regular Clients'!$J$6:$J$30<>"Ended")*('Regular Clients'!$J$6:$J$30<>"Not started"))>1,"CLASH",INDEX('Regular Clients'!$A$6:$A$30,SUMPRODUCT(MAX(('Regular Clients'!$C$6:$C$30=H$5)*('Regular Clients'!$B$6:$B$30=$B$3)*('Regular Clients'!$D$6:$D$30<=$A13)*('Regular Clients'!$E$6:$E$30>$A13)*('Regular Clients'!$J$6:$J$30<>"Ended")*('Regular Clients'!$J$6:$J$30<>"Not started")*(ROW('Regular Clients'!$A$6:$A$30)-ROW('Regular Clients'!$A$6)+1))))))
